2023-04-13 18:08:46,306 : INFO : root : Loading config.
2023-04-13 18:08:46,312 : INFO : YamlMultifileConfigLoader : Machine config file #1: config.yaml
2023-04-13 18:08:46,313 : WARNING : ConfigProcessor : Config file in cache changed: C:\pinball\greatest_showman\config\config.yaml
2023-04-13 18:08:46,313 : INFO : ConfigProcessor : Loading config from file C:\Users\lisas\.local\pipx\venvs\mpf\lib\site-packages\mpf\mpfconfig.yaml.
2023-04-13 18:08:46,369 : INFO : ConfigProcessor : Loading config: C:\Users\lisas\.local\pipx\venvs\mpf\lib\site-packages\mpf\mpfconfig.yaml
2023-04-13 18:08:46,369 : INFO : ConfigProcessor : Loading config from file C:\pinball\greatest_showman\config\config.yaml.
2023-04-13 18:08:46,377 : INFO : ConfigProcessor : Loading config: C:\pinball\greatest_showman\config\config.yaml
2023-04-13 18:08:46,378 : INFO : ConfigProcessor : Config file cache created: C:\Users\lisas\AppData\Local\Temp\c5e3c6a6b44933afaf432493a3c7f734.mpf_cache
2023-04-13 18:08:46,453 : INFO : ConfigProcessor : Loading config from cache: C:\Users\lisas\AppData\Local\Temp\2591d1a5aee1eec0eefe4740cb1b00b0.mpf_cache
2023-04-13 18:08:46,457 : INFO : ConfigProcessor : Loading config from cache: C:\Users\lisas\AppData\Local\Temp\b5a4e895e7586a66014791409c611ae3.mpf_cache
2023-04-13 18:08:46,460 : INFO : Machine : Mission Pinball Framework Core Engine v0.56.0
2023-04-13 18:08:46,461 : INFO : Machine : Command line arguments: {'no_load_cache': False, 'create_config_cache': True, 'bcp': False, 'configfile': ['config.yaml'], 'force_assets_load': False, 'jsonlogging': False, 'logfile': 'logs\\2023-04-13-18-08-46-mpf-LisaDesktop.log', 'pause': False, 'production': False, 'text_ui': False, 'loglevel': 15, 'consoleloglevel': 20, 'force_platform': None, 'syslog_address': None, 'mc_file_name': None, 'no_sound': False}
2023-04-13 18:08:46,461 : INFO : Machine : MPF path: C:\Users\lisas\.local\pipx\venvs\mpf\lib\site-packages\mpf
2023-04-13 18:08:46,461 : INFO : Machine : Machine path: C:\pinball\greatest_showman
2023-04-13 18:08:46,461 : INFO : Machine : Platform: win32
2023-04-13 18:08:46,461 : INFO : Machine : Python executable location: C:\Users\lisas\.local\pipx\venvs\mpf\Scripts\python.exe
2023-04-13 18:08:46,461 : INFO : Machine : Python version: 3.9.13 (64-bit)
2023-04-13 18:08:46,463 : INFO : Machine : Initialise MPF.
2023-04-13 18:08:46,633 : INFO : FAST : Connecting to com4 at 921600bps
2023-04-13 18:08:46,634 : INFO : Machine : Shutting down...
2023-04-13 18:08:46,634 : INFO : EventManager : Event: ======'shutdown'====== Args={}
2023-04-13 18:08:46,746 : ERROR : Machine : Failed to initialise MPF
Traceback (most recent call last):
  File "C:\Users\lisas\.local\pipx\venvs\mpf\lib\site-packages\mpf\platforms\fast\fast.py", line 318, in _connect_to_hardware
    await comm.connect()
  File "C:\Users\lisas\.local\pipx\venvs\mpf\lib\site-packages\mpf\platforms\base_serial_communicator.py", line 47, in connect
    await self._connect_to_hardware(self.port, self.baud, self.xonxoff)
  File "C:\Users\lisas\.local\pipx\venvs\mpf\lib\site-packages\mpf\platforms\base_serial_communicator.py", line 56, in _connect_to_hardware
    self.reader, self.writer = await connector
  File "C:\Users\lisas\.local\pipx\venvs\mpf\lib\site-packages\mpf\core\clock.py", line 152, in open_serial_connection
    transport, _ = await create_serial_connection(
  File "C:\Users\lisas\AppData\Local\Programs\Python\Python39\lib\asyncio\coroutines.py", line 124, in coro
    res = func(*args, **kw)
  File "C:\Users\lisas\.local\pipx\venvs\mpf\lib\site-packages\serial_asyncio\__init__.py", line 410, in create_serial_connection
    ser = serial.serial_for_url(*args, **kwargs)
  File "C:\Users\lisas\.local\pipx\venvs\mpf\lib\site-packages\serial\__init__.py", line 90, in serial_for_url
    instance.open()
  File "C:\Users\lisas\.local\pipx\venvs\mpf\lib\site-packages\serial\serialwin32.py", line 64, in open
    raise SerialException("could not open port {!r}: {!r}".format(self.portstr, ctypes.WinError()))
serial.serialutil.SerialException: could not open port 'com4': FileNotFoundError(2, 'The system cannot find the file specified.', None, 2)

The above exception was the direct cause of the following exception:

Traceback (most recent call last):
  File "C:\Users\lisas\.local\pipx\venvs\mpf\lib\site-packages\mpf\core\machine.py", line 679, in initialise_mpf
    raise init.exception()
  File "C:\Users\lisas\.local\pipx\venvs\mpf\lib\site-packages\mpf\core\machine.py", line 246, in initialise
    await self.initialise_core_and_hardware()
  File "C:\Users\lisas\.local\pipx\venvs\mpf\lib\site-packages\mpf\core\machine.py", line 242, in initialise_core_and_hardware
    await self._initialize_platforms()
  File "C:\Users\lisas\.local\pipx\venvs\mpf\lib\site-packages\mpf\core\machine.py", line 333, in _initialize_platforms
    result.result()
  File "C:\Users\lisas\.local\pipx\venvs\mpf\lib\site-packages\mpf\platforms\fast\fast.py", line 186, in initialize
    await self._connect_to_hardware()
  File "C:\Users\lisas\.local\pipx\venvs\mpf\lib\site-packages\mpf\platforms\fast\fast.py", line 320, in _connect_to_hardware
    raise MpfRuntimeError("Could not open serial port {}. Check if you configured the correct port in the "
mpf.exceptions.runtime_error.MpfRuntimeError: Runtime Error in FAST: Could not open serial port com4. Check if you configured the correct port in the fast config section and if you got sufficient permissions to that port Error Code: RE-FAST-1 (https://docs.missionpinball.org/en/0.56/logs/RE-FAST-1.html)
2023-04-13 18:09:01,750 : INFO : root : MPF run loop ended.
